Workbook

Sheet Hardware
A1: HARDWARE CAPITAL EXPENDITURE — On-Premise ACE Platform @ 1,000 Orders/Day
A2: Item | B2: Qty | C2: Unit Cost (USD) | D2: Yr2 Refresh % | E2: Year 1 Total | F2: Year 2 Total | G2: Year 3 Total | H2: Specification / Notes
A3: APPLICATION & DATABASE SERVERS
A4: App server — Dell PowerEdge R650 (2×Xeon Silver 4314, 128GB RAM, 2×960GB SSD RAID-1) | B4: 2 | C4: 8200 | D4: 0 | E4: =B4*C4 -> 16400 | F4: =E4*D4 -> 0 | G4: =E4*D4 -> 0 | H4: Primary + HA standby. Hosts: order API, auth, KYC, market data, reporting, session mgr
A5: Database server — Dell PowerEdge R750 (2×Xeon Gold 5318Y, 512GB RAM, 4×3.84TB NVMe) | B5: 2 | C5: 14500 | D5: 0 | E5: =B5*C5 -> 29000 | F5: =E5*D5 -> 0 | G5: =E5*D5 -> 0 | H5: Primary + standby. PostgreSQL 15 + TimescaleDB tick store. NVMe critical for WAL speed
A6: Matching engine server — Supermicro 1U (2×Xeon Gold 6342, 256GB RAM, 2×NVMe SSD) | B6: 2 | C6: 11800 | D6: 0 | E6: =B6*C6 -> 23600 | F6: =E6*D6 -> 0 | G6: =E6*D6 -> 0 | H6: Dedicated CPU-opt nodes for CLOB + order matching. N+1 mandatory. Never under-spec.
A7: Kafka broker — Dell R650 (2×Xeon Silver, 128GB RAM, 6×2TB HDD RAID-10) | B7: 3 | C7: 6400 | D7: 0 | E7: =B7*C7 -> 19200 | F7: =E7*D7 -> 0 | G7: =E7*D7 -> 0 | H7: 3-node Kafka cluster. Replication factor 3. Hosts MSK-equivalent for all event streams
A8: Backup / archive server — Dell PowerEdge R540 (1×Xeon Silver, 64GB RAM, 4×4TB HDD) | B8: 1 | C8: 4200 | D8: 0 | E8: =B8*C8 -> 4200 | F8: =E8*D8 -> 0 | G8: =E8*D8 -> 0 | H8: Full system backup + off-site Veeam replication target. Doubles as DR hot-standby
A9: Monitoring / bastion server — Dell R350 (1×Xeon E, 32GB RAM) | B9: 1 | C9: 2800 | D9: 0 | E9: =B9*C9 -> 2800 | F9: =E9*D9 -> 0 | G9: =E9*D9 -> 0 | H9: Grafana, Prometheus, ELK stack, GitLab runner, Ansible. Out-of-band management
A10: NETWORK EQUIPMENT
A11: Core switch — Cisco Catalyst 9300L-48T-4G (L3, 48-port GbE, 4×10G SFP+) — pair | B11: 2 | C11: 4600 | D11: 0 | E11: =B11*C11 -> 9200 | F11: =E11*D11 -> 0 | G11: =E11*D11 -> 0 | H11: Redundant HSRP active/standby pair. 10GbE uplinks to all servers. VLAN-segmented tiers
A12: Access switch — Cisco Catalyst 9200L-24T (L2, 24-port) — pair | B12: 2 | C12: 1800 | D12: 0 | E12: =B12*C12 -> 3600 | F12: =E12*D12 -> 0 | G12: =E12*D12 -> 0 | H12: Top-of-rack access layer. One per rack. Uplink to core via 10GbE LAG
A13: Next-gen firewall — Fortinet FortiGate 100F (2Gbps NGFW, IPS, WAF) — HA pair | B13: 2 | C13: 4200 | D13: 0 | E13: =B13*C13 -> 8400 | F13: =E13*D13 -> 0 | G13: =E13*D13 -> 0 | H13: Active/passive HA. WAF, IPS, URL filter, SSL inspection. Regulatory security baseline
A14: Router — Cisco ISR 4321 (dual WAN, BGP, QoS) | B14: 1 | C14: 2600 | D14: 0 | E14: =B14*C14 -> 2600 | F14: =E14*D14 -> 0 | G14: =E14*D14 -> 0 | H14: Dual-ISP failover via BGP. QoS prioritises trading traffic over management traffic
A15: 10GbE SFP+ modules, DAC cables, 1GbE patch cables (bulk) | B15: 1 | C15: 1700 | D15: 0 | E15: =B15*C15 -> 1700 | F15: =E15*D15 -> 0 | G15: =E15*D15 -> 0 | H15: 20× SFP+ DAC + 20× fibre SFPs + 50× Cat6A patch cables. Full structured cabling
A16: STORAGE SYSTEMS
A17: NAS — Synology RS3621RPxs (12-bay, 2×10GbE, redundant PSU) + 8×18TB Exos | B17: 2 | C17: 9800 | D17: 0 | E17: =B17*C17 -> 19600 | F17: =E17*D17 -> 0 | G17: =E17*D17 -> 0 | H17: RAID-6 → 96TB usable per unit. Warehouse docs, audit logs, reports, database backups
A18: Tape library — Quantum Scalar i3 LTO-9 (2-drive, 50-slot autoloader) | B18: 1 | C18: 12000 | D18: 0 | E18: =B18*C18 -> 12000 | F18: =E18*D18 -> 0 | G18: =E18*D18 -> 0 | H18: 7-year regulatory archive. 18TB native/cartridge. Air-gapped, tamper-evident, off-site copy
A19: LTO-9 tape cartridges (50-pack × 2 sets) | B19: 2 | C19: 950 | D19: 0 | E19: =B19*C19 -> 1900 | F19: =E19*D19 -> 0 | G19: =E19*D19 -> 0 | H19: 100 carts = ~1.8PB native. 3-year initial supply. Monthly off-site rotation to vault
A20: Spare enterprise NVMe — Samsung PM9A3 3.84TB (pool of 4) | B20: 4 | C20: 680 | D20: 0 | E20: =B20*C20 -> 2720 | F20: =E20*D20 -> 0 | G20: =E20*D20 -> 0 | H20: Hot-spare pool for database nodes. Same-day swap on failure keeps RTO < 2hrs
A21: UPS & POWER INFRASTRUCTURE
A22: UPS — APC Smart-UPS Ultra 5kVA Li-Ion rack-mount (pair) | B22: 2 | C22: 4800 | D22: 0 | E22: =B22*C22 -> 9600 | F22: =E22*D22 -> 0 | G22: =E22*D22 -> 0 | H22: ~20 min runtime at full 5kW load. Enough for graceful shutdown + generator start
A23: Monitored rack PDU — APC AP8958 Switched 32A (2 per rack × 2 racks) | B23: 4 | C23: 620 | D23: 0 | E23: =B23*C23 -> 2480 | F23: =E23*D23 -> 0 | G23: =E23*D23 -> 0 | H23: Per-outlet current monitoring. Remote power cycle for locked-up servers without on-site visit
A24: Standby diesel generator — 20kVA (automatic transfer switch included) | B24: 1 | C24: 8500 | D24: 0 | E24: =B24*C24 -> 8500 | F24: =E24*D24 -> 0 | G24: =E24*D24 -> 0 | H24: Full site load at 5.5kW = 27% of 20kVA rating. Ample headroom. Quarterly test run.
A25: RACKS & PHYSICAL INFRASTRUCTURE
A26: Server rack — APC NetShelter SX 42U 600mm with front/rear doors (pair) | B26: 2 | C26: 1800 | D26: 0 | E26: =B26*C26 -> 3600 | F26: =E26*D26 -> 0 | G26: =E26*D26 -> 0 | H26: 2 racks covers all servers + networking + UPS with 30% expansion headroom
A27: 48-port Cat6A patch panel + structured cabling (per rack) | B27: 2 | C27: 950 | D27: 0 | E27: =B27*C27 -> 1900 | F27: =E27*D27 -> 0 | G27: =E27*D27 -> 0 | H27: All server-to-switch links pre-terminated. Cable management arms. Clean cable dress.
A28: KVM-over-IP console server — Raritan Dominion LX2-116 (16-port) | B28: 1 | C28: 1200 | D28: 0 | E28: =B28*C28 -> 1200 | F28: =E28*D28 -> 0 | G28: =E28*D28 -> 0 | H28: Out-of-band management independent of production network. Required for remote DR ops
A29: Asset tagging, label printer, documentation kit | B29: 1 | C29: 400 | D29: 0 | E29: =B29*C29 -> 400 | F29: =E29*D29 -> 0 | G29: =E29*D29 -> 0 | H29: Physical CMDB asset register. Every device QR-tagged with CMDB link
A30: INSTALLATION & SETUP LABOR
A31: Hardware racking, cabling, base OS installation (3-day on-site) | B31: 1 | C31: 4500 | D31: 0 | E31: =B31*C31 -> 4500 | F31: =E31*D31 -> 0 | G31: =E31*D31 -> 0 | H31: Professional tech. Server racking, cable dress, RHEL install on all nodes, BIOS config
A32: Network design implementation & testing (2-day) | B32: 1 | C32: 2800 | D32: 0 | E32: =B32*C32 -> 2800 | F32: =E32*D32 -> 0 | G32: =E32*D32 -> 0 | H32: VLAN setup, firewall rules, BGP config, HSRP/failover testing, bandwidth measurement
A33: 48-hour burn-in / stress test + performance baseline documentation | B33: 1 | C33: 1200 | D33: 0 | E33: =B33*C33 -> 1200 | F33: =E33*D33 -> 0 | G33: =E33*D33 -> 0 | H33: Sustained load test before production handoff. Confirms no infant-mortality hardware failures
A34: TOTAL HARDWARE CAPEX | E34: =SUM(E3:E33) -> 193100 | F34: =SUM(F3:F33) -> 0 | G34: =SUM(G3:G33) -> 0

Sheet Software
A1: SOFTWARE LICENSES & SUBSCRIPTIONS
A2: Software / License | B2: Year 1 (USD) | C2: Year 2 (USD) | D2: Year 3 (USD) | E2: License Type | F2: Notes
A3: OPERATING SYSTEM & VIRTUALISATION
A4: RHEL 9 Server (per socket pair) — 11 servers × 2 sockets = 22 sub-pairs | B4: 3200 | C4: 3200 | D4: 3200 | E4: Annual subscription | F4: Includes errata, security patches, 24/7 Red Hat TAC. Mandatory for regulated prod env.
A5: VMware vSphere Essentials Plus Kit (3 hosts) | B5: 3600 | C5: 1800 | D5: 1800 | E5: Perpetual + annual renew | F5: VM layer for app servers. Snapshot-based rollback on deployment failures. Optional but recommended.
A6: DATABASE (OPEN SOURCE — NO LICENSE COST)
A7: PostgreSQL 15 Community Edition | B7: 0 | C7: 0 | D7: 0 | E7: Open source (PostgreSQL License) | F7: OLTP: orders, accounts, compliance, audit. Production support via RHEL subscription.
A8: TimescaleDB Community Edition | B8: 0 | C8: 0 | D8: 0 | E8: Open source (Apache 2.0) | F8: Tick data hypertables. Community tier free. Enterprise (compression+cont.agg): ~$20K/yr in Year 2.
A9: pgBackRest — WAL archive & point-in-time recovery | B9: 0 | C9: 0 | D9: 0 | E9: Open source (MIT) | F9: No cost. Handles full + incremental backup and PITR recovery for PostgreSQL.
A10: MESSAGE BUS
A11: Apache Kafka (via Confluent Community / KRaft mode) | B11: 0 | C11: 0 | D11: 0 | E11: Open source (Apache 2.0) | F11: No license. If Confluent Platform support needed later: est. $25K/yr — evaluate in Year 2.
A12: MONITORING & OBSERVABILITY
A13: Grafana Enterprise — 5-seat team license | B13: 1200 | C13: 1200 | D13: 1200 | E13: Annual subscription | F13: Dashboards, alerting, on-call routing. 5 seats sufficient for ops team.
A14: Prometheus + Alertmanager | B14: 0 | C14: 0 | D14: 0 | E14: Open source (Apache 2.0) | F14: Metrics collection. No cost. Scrapes all service endpoints.
A15: Elastic Stack (Elasticsearch + Kibana) Basic tier | B15: 0 | C15: 0 | D15: 0 | E15: Open source (Elastic License) | F15: Log aggregation, full-text search for audit. Basic is free. Platinum adds SIEM alerting.
A16: SECURITY
A17: Fortinet FortiCare 360 + FortiGuard UTM (both FW units) | B17: 1800 | C17: 1800 | D17: 1800 | E17: Annual renewal | F17: IPS signatures, AV, URL filtering, app control. Both HA firewall units.
A18: Qualys Vulnerability Management VMDR (16 IPs) | B18: 2400 | C18: 2400 | D18: 2400 | E18: Annual subscription | F18: Continuous vuln scanning. Required for compliance sign-off from regulator.
A19: Wildcard TLS certificate — *.ace-exchange.mn | B19: 300 | C19: 300 | D19: 300 | E19: Annual renewal | F19: All public-facing HTTPS endpoints. DigiCert or Sectigo OV wildcard.
A20: BACKUP & RECOVERY
A21: Veeam Backup & Replication Universal License (10 workloads) | B21: 2800 | C21: 1400 | D21: 1400 | E21: Perpetual + 1yr maint | F21: VM and physical backup. Tape target integration. PITR for any workload.
A22: CONTAINER ORCHESTRATION
A23: Rancher RKE2 / K3s (on-premise Kubernetes) | B23: 0 | C23: 0 | D23: 0 | E23: Open source (Apache 2.0) | F23: Production-grade Kubernetes distribution for bare-metal. SUSE Rancher UI optional.
A24: Harbor container registry (self-hosted) | B24: 0 | C24: 0 | D24: 0 | E24: Open source (Apache 2.0) | F24: Air-gapped private OCI registry. All service images pulled from Harbor, not public internet.
A25: DEVELOPER & CI/CD TOOLING
A26: GitLab Community Edition (self-hosted) | B26: 0 | C26: 0 | D26: 0 | E26: Open source (MIT) | F26: Git, CI/CD pipelines, issue tracker, secrets management. No license.
A27: HashiCorp Terraform (BSL — internal use free) | B27: 0 | C27: 0 | D27: 0 | E27: BSL 1.1 | F27: IaC for all infrastructure. Internal use is free under BSL.
A28: COMPLIANCE & FINANCIAL
A29: PEP / sanctions watchlist data feed (ACAMS / Dow Jones) | B29: 1200 | C29: 1200 | D29: 1200 | E29: Annual data subscription | F29: PEP database, sanctions list, adverse media. Required for KYC/AML engine (T016).
A30: Legal Entity Identifier (LEI) — initial + annual maintenance | B30: 200 | C30: 100 | D30: 100 | E30: Annual | F30: Exchange LEI for regulatory trade reporting. GLEIF registration.
A31: PRODUCTIVITY
A32: Microsoft 365 Business Standard — 10 users | B32: 1320 | C32: 1320 | D32: 1320 | E32: Annual subscription | F32: Exchange, Teams, SharePoint. For ops + management team communication.
A33: TOTAL SOFTWARE | B33: =SUM(B3:B32) -> 18020 | C33: =SUM(C3:C32) -> 14720 | D33: =SUM(D3:D32) -> 14720

Sheet OpEx
A1: ANNUAL OPERATING EXPENDITURE — Facilities · Power · Staffing · Connectivity · Maintenance
A2: Item | B2: Year 1 (USD) | C2: Year 2 (USD) | D2: Year 3 (USD) | E2: Basis | F2: Notes
A3: COLOCATION / DATACENTER SPACE
A4: Datacenter co-lo — 25 sqm secured room, Ulaanbaatar | B4: 6000 | C4: 6360 | D4: 6742 | E4: Annual lease | F4: Includes biometric access, CCTV, fire suppression, climate control, 24/7 physical security
A5: After-hours datacenter access & colo staff support | B5: 600 | C5: 620 | D5: 640 | E5: Annual | F5: Emergency callout fees, escort access outside business hours
A6: POWER & COOLING
A7: Electricity — IT load 5.5kW avg × PUE 1.2 × $0.065/kWh | B7: 4557 | C7: 4785 | D7: 5024 | E7: Annual (kWh)
A8: Generator diesel fuel + quarterly service contract | B8: 1800 | C8: 1850 | D8: 1910 | E8: Annual | F8: Diesel reserve (200L) + 4× professional test runs/year with certified engineer
A9: UPS Li-Ion battery replacement reserve (5-yr amortised) | B9: 960 | C9: 960 | D9: 960 | E9: Annual accrual | F9: 2 units × $4,800 replacement ÷ 5yr = $1,920/yr ÷ 2 = $960 annual accrual
A10: HVAC / precision cooling maintenance contract | B10: 1200 | C10: 1240 | D10: 1280 | E10: Annual contract | F10: Bi-annual service + refrigerant top-up. Dedicated precision AC units for server room
A11: IT PERSONNEL (MONGOLIA MARKET RATES)
A12: Systems / infrastructure engineer — 1.0 FTE | B12: 18000 | C12: 19800 | D12: 21780 | E12: Annual salary | F12: Mid-level. RHEL, Kubernetes, networking, storage, backup ops. +10% raise/yr assumed
A13: Database administrator — 0.5 FTE (shared role) | B13: 9000 | C13: 9900 | D13: 10890 | E13: Annual salary | F13: PostgreSQL + TimescaleDB tuning, backup verification, schema migrations
A14: Security & compliance officer — 0.5 FTE (shared role) | B14: 9000 | C14: 9900 | D14: 10890 | E14: Annual salary | F14: Firewall policy, vuln scanning, KYC ops review, audit log monitoring, regulator reports
A15: On-call allowance (24/7 exchange coverage rotation) | B15: 3600 | C15: 3780 | D15: 3970 | E15: Annual allowance | F15: Shift differential + on-call stipend. Exchange cannot go unmonitored outside business hours
A16: HARDWARE MAINTENANCE & VENDOR SUPPORT
A17: Dell ProSupport Plus NBD on-site — all 11 servers | B17: 4840 | C17: 4840 | D17: 4840 | E17: Annual contract | F17: $440/server/yr. Next-business-day on-site tech + parts. Non-negotiable for SLA
A18: Cisco SmartNet — 2×Cat9300L + 2×Cat9200L + ISR4321 | B18: 3200 | C18: 3200 | D18: 3200 | E18: Annual contract | F18: 24/7 Cisco TAC + software updates + hardware RMA. Full network stack covered
A19: Fortinet FortiCare 360 — both FortiGate 100F units | B19: 1600 | C19: 1600 | D19: 1600 | E19: Annual contract | F19: 24/7 TAC + firmware updates + RMA for HA pair. Includes UTM signature subscription
A20: Synology extended warranty — both NAS units | B20: 400 | C20: 400 | D20: 400 | E20: Annual contract | F20: Extended to 5-yr coverage. NBD advance-replacement.
A21: Tape library service + cleaning cartridges | B21: 240 | C21: 240 | D21: 240 | E21: Annual | F21: Quantum Scalar i3 preventive maintenance + LTO-9 cleaning tapes
A22: NETWORK CONNECTIVITY
A23: Primary internet — 1 Gbps dedicated symmetric fiber (Mobicom) | B23: 6000 | C23: 6000 | D23: 6000 | E23: Annual | F23: Dedicated line to datacenter. Broker API, web terminal, market data WebSocket feeds
A24: Failover internet — 500 Mbps (Unitel or G-Mobile) | B24: 3600 | C24: 3600 | D24: 3600 | E24: Annual | F24: Separate ISP for BGP dual-homing. Automatic switchover. Prevents single-ISP outage
A25: MPLS leased line — datacenter to central bank / settlement | B25: 4800 | C25: 4800 | D25: 4800 | E25: Annual | F25: Private circuit for RTGS payment settlement. Regulatory requirement for licensed exchange
A26: Static IP allocation fees (both ISPs) | B26: 360 | C26: 360 | D26: 360 | E26: Annual | F26: Public /29 block per ISP = 5 usable IPs each. Required for BGP and inbound broker access
A27: INSURANCE & COMPLIANCE
A28: Cyber liability insurance | B28: 3600 | C28: 3600 | D28: 3600 | E28: Annual premium | F28: Covers breach notification, forensics, recovery. Required by financial regulator.
A29: Hardware all-risk equipment insurance (~$250K replacement value) | B29: 1200 | C29: 1200 | D29: 1200 | E29: Annual premium | F29: Fire, flood, theft, accidental damage. Covers full hardware replacement cost
A30: MISCELLANEOUS OPERATIONAL
A31: Consumables — tapes, labels, SFP spares, cables, tools | B31: 600 | C31: 600 | D31: 600 | E31: Annual | F31: Monthly consumable budget: blank cartridges, SFP spare pool, patch cables, cleaning
A32: Staff training & certifications (RHCSA, CCNA, security) | B32: 2400 | C32: 2000 | D32: 2000 | E32: Annual | F32: Critical skills maintenance for small team. Certifications support vendor support escalation
A33: ITSM & monitoring tooling — Atlassian JSM Cloud (incident mgmt) | B33: 900 | C33: 900 | D33: 900 | E33: Annual | F33: Incident tracking, on-call scheduling, change management. 5-user Jira Service Mgmt.
A34: TOTAL ANNUAL OPEX | B34: =SUM(B3:B33) -> 88457 | C34: =SUM(C3:C33) -> 92535 | D34: =SUM(D3:D33) -> 97426

Sheet TCO Summary
A1: 3-YEAR TOTAL COST OF OWNERSHIP — On-Premise ACE Platform @ 1,000 Orders/Day
A2: All costs USD | Blue text = inputs you can change | Black text = calculated formulas | Cloud reference: ADR-001 = $9,210/month (AWS Tokyo)
A4: ASSUMPTIONS
A5: Orders per day (design capacity) | C5: 1000
A6: Annual order volume growth rate | C6: 0.3
A7: Site | C7: Ulaanbaatar, Mongolia
A8: Electricity cost USD/kWh | C8: 0.065
A9: MNT/USD exchange rate | C9: 3450
A10: AWS cloud monthly cost (reference) | C10: 9210
A11: On-prem contingency buffer | C11: 0.1
A13: Cost Category | C13: Year 1 | D13: Year 2 | E13: Year 3 | F13: 3-Year Total | G13: % of TCO
A14: Server & network hardware CapEx | C14: =Hardware!E34 -> 193100 | D14: =Hardware!F34 -> 0 | E14: =Hardware!G34 -> 0 | F14: =SUM(C14:E14) -> 193100 | G14: =IFERROR(F14/F24,"-") -> 0.33825221
A15: Software licenses | C15: =Software!B33 -> 18020 | D15: =Software!C33 -> 14720 | E15: =Software!D33 -> 14720 | F15: =SUM(C15:E15) -> 47460 | G15: =IFERROR(F15/F24,"-") -> 0.083135421
A16: Colocation / datacenter space | C16: =SUM(OpEx!B4:B5) -> 6600 | D16: =SUM(OpEx!C4:C5) -> 6980 | E16: =SUM(OpEx!D4:D5) -> 7382 | F16: =SUM(C16:E16) -> 20962 | G16: =IFERROR(F16/F24,"-") -> 0.03671902
A17: Power & cooling (electricity+gen) | C17: =SUM(OpEx!B7:B10) -> 8517 | D17: =SUM(OpEx!C7:C10) -> 8835 | E17: =SUM(OpEx!D7:D10) -> 9174 | F17: =SUM(C17:E17) -> 26526 | G17: =IFERROR(F17/F24,"-") -> 0.046465448
A18: IT personnel | C18: =SUM(OpEx!B12:B15) -> 39600 | D18: =SUM(OpEx!C12:C15) -> 43380 | E18: =SUM(OpEx!D12:D15) -> 47530 | F18: =SUM(C18:E18) -> 130510 | G18: =IFERROR(F18/F24,"-") -> 0.22861365
A19: Hardware maintenance & support | C19: =SUM(OpEx!B17:B21) -> 10280 | D19: =SUM(OpEx!C17:C21) -> 10280 | E19: =SUM(OpEx!D17:D21) -> 10280 | F19: =SUM(C19:E19) -> 30840 | G19: =IFERROR(F19/F24,"-") -> 0.054022258
A20: Network connectivity | C20: =SUM(OpEx!B23:B26) -> 14760 | D20: =SUM(OpEx!C23:C26) -> 14760 | E20: =SUM(OpEx!D23:D26) -> 14760 | F20: =SUM(C20:E20) -> 44280 | G20: =IFERROR(F20/F24,"-") -> 0.077565033
A21: Insurance & compliance | C21: =SUM(OpEx!B28:B29) -> 4800 | D21: =SUM(OpEx!C28:C29) -> 4800 | E21: =SUM(OpEx!D28:D29) -> 4800 | F21: =SUM(C21:E21) -> 14400 | G21: =IFERROR(F21/F24,"-") -> 0.025224401
A22: Misc operational | C22: =SUM(OpEx!B31:B33) -> 3900 | D22: =SUM(OpEx!C31:C33) -> 3500 | E22: =SUM(OpEx!D31:D33) -> 3500 | F22: =SUM(C22:E22) -> 10900 | G22: =IFERROR(F22/F24,"-") -> 0.01909347
A23: Contingency (10% of subtotal) | C23: =SUM(C14:C22)*C11 -> 29957.7 | D23: =SUM(D14:D22)*C11 -> 10725.5 | E23: =SUM(E14:E22)*C11 -> 11214.6 | F23: =SUM(C23:E23) -> 51897.8 | G23: =IFERROR(F23/F24,"-") -> 0.090909091
A24: GRAND TOTAL TCO | C24: =SUM(C14:C23) -> 329534.7 | D24: =SUM(D14:D23) -> 117980.5 | E24: =SUM(E14:E23) -> 123360.6 | F24: =SUM(F14:F23) -> 570875.8
A26: UNIT ECONOMICS & CLOUD COMPARISON
A27: Monthly avg run cost (3-yr basis) | C27: =F24/36 -> 15857.661
A28: Daily run cost | C28: =F24/(3*365) -> 521.34776
A29: Cost per order (1,000/day avg) | C29: =(F24/(3*365*1000)) -> 0.52134776
A30: AWS cloud 3-yr cost (reference) | C30: =C10*36 -> 331560
A31: On-prem 3-yr saving vs cloud | C31: =(C10*36)-F24 -> -239315.8
A32: On-prem saving % vs cloud | C32: =IFERROR(((C10*36)-F24)/(C10*36),"-") -> -0.72178731
A35: LEGEND: Blue text = hardcoded input (can be changed) | Black text = Excel formula | Yellow background = critical assumption requiring local verification

Sheet Sizing Notes
A1: CAPACITY SIZING RATIONALE — 1,000 Orders/Day On-Premise Exchange
A2: DAILY LOAD PROFILE
A3: Metric | B3: Value | C3: Calc basis | D3: Peak (5× avg) | E3: Notes
A4: Orders per day | B4: 1,000 | C4: Input | D4: 5,000/day (burst) | E4: Design capacity. Both buy + sell orders included
A5: Orders per hour (avg) | B5: 42 | C5: 1,000 ÷ 24 | D5: 208/hr | E5: Market hours heavier — see peak
A6: Orders per minute (avg) | B6: 0.7 | C6: 1,000 ÷ 1,440 | D6: 3.5/min | E6: Very low rate. Hardware is 10–50× over-provisioned intentionally
A7: Market open peak burst | B7: ~200/hr | C7: 5× avg | D7: Opening auction | E7: Morning auction is the single highest-concurrency window
A8: Trades generated/day | B8: ~300 | C8: 30% fill rate | D8: ~600/day peak | E8: Partial fills counted as 1 trade each
A9: Warehouse receipts/day | B9: ~50 | C9: Estimate | D9: — | E9: Low physical delivery volume at exchange launch
A10: Tick data writes/day | B10: ~50,000 | C10: All order+trade events | D10: 250K/day peak | E10: TimescaleDB handles 1M+ inserts/sec on chosen hardware
A11: SERVER SIZING JUSTIFICATION
A12: Component | B12: Spec chosen | C12: Minimum needed | D12: Headroom ratio | E12: Scale-up trigger
A13: App servers (×2) | B13: Dell R650, 128GB RAM, NVMe SSD | C13: ~8GB RAM, 4 vCPU | D13: 16× RAM headroom | E13: Add 3rd node if order rate exceeds 15,000/day
A14: Matching engine (×2) | B14: Supermicro, Xeon Gold 6342, 256GB | C14: ~2 vCPU, 8GB needed | D14: 50× headroom | E14: N+1 is non-negotiable. Never reduce spec. Critical SLA path.
A15: DB server (×2) | B15: Dell R750, 512GB RAM, 4×3.84TB NVMe | C15: ~16GB RAM, NVMe WAL | D15: 32× headroom | E15: Add read replicas when report queries exceed 2s at current spec
A16: Kafka brokers (×3) | B16: Dell R650, 128GB, 6×2TB HDD | C16: ~10GB/day raw logs | D16: ~200 days buffer | E16: Increase storage if data feed volume exceeds 30GB/day
A17: NAS storage (×2 units) | B17: 96TB usable RAID-6 each | C17: ~2TB/yr at launch | D17: 48× headroom | E17: 7-yr regulatory archive fits in 14TB; 192TB total covers 50+ years
A18: Backup/archive server | B18: Dell R540, 64GB, 4×4TB HDD | C18: ~2TB/day backup | D18: 2 weeks local | E18: Tape library handles 7-yr archive. Local disk = 14-day rolling
A19: POWER CONSUMPTION BREAKDOWN
A20: Component | B20: Count | C20: TDP (Watts) | D20: Total Watts | E20: Annual kWh
A21: App servers | B21: 2 | C21: 300W | D21: 600W | E21: 5,256
A22: Matching engine servers | B22: 2 | C22: 350W | D22: 700W | E22: 6,132
A23: Database servers | B23: 2 | C23: 400W | D23: 800W | E23: 7,008
A24: Kafka broker servers | B24: 3 | C24: 250W | D24: 750W | E24: 6,570
A25: Backup + monitoring servers | B25: 2 | C25: 200W | D25: 400W | E25: 3,504
A26: Networking (switches+FW+router) | B26: 1 | C26: 600W combined | D26: 600W | E26: 5,256
A27: NAS + tape library | B27: 1 | C27: 300W combined | D27: 300W | E27: 2,628
A28: UPS overhead (10% of IT load) | B28: — | C28: — | D28: 415W | E28: 3,635
A29: IT load subtotal | B29: — | C29: — | D29: 4,565W | E29: 39,989
A30: With PUE 1.2 (cooling overhead) | B30: — | C30: — | D30: 5,478W avg | E30: 47,987 kWh/yr
A31: Annual electricity cost @ $0.065/kWh | B31: — | C31: — | D31: — | E31: $3,119/yr IT only
A32: NETWORK BANDWIDTH SIZING
A33: Traffic type | B33: Avg bandwidth | C33: Peak bandwidth | D33: ISP provisioned | E33: Headroom
A34: Broker FIX + REST trading API | B34: 5 Mbps | C34: 50 Mbps | D34: 1 Gbps | E34: 20×
A35: Market data WebSocket feeds | B35: 10 Mbps | C35: 80 Mbps | D35: 1 Gbps | E35: 12×
A36: Web trading terminal (HTTPS) | B36: 2 Mbps | C36: 20 Mbps | D36: 1 Gbps | E36: 50×
A37: Settlement MPLS circuit | B37: 1 Mbps | C37: 5 Mbps | D37: 10 Mbps dedicated | E37: 2×
A38: Management & monitoring | B38: 1 Mbps | C38: 10 Mbps | D38: Internal VLAN | E38: —
A39: TOTAL primary ISP requirement | B39: ~20 Mbps avg | C39: ~160 Mbps peak | D39: 1 Gbps provisioned | E39: 6× peak headroom
A40: WHEN TO SCALE UP (TRIGGER POINTS)
...
